Workbook

Sheet Summary
A2: Champions Retreat Golf Club - Summary Page for 2026 Projects
A3: 8/15/2025 (updated on 2-19-26)
A4: Preliminary Bill of Quantities
A5: Other Costs / Items to Consider: Soft Costs and Landscaping
A6: Practice Facilities (Practice Range and Short Game Area) | F6: Two Large Putting Greens and Event Lawn | K6: Re-Build Bunkers (all 27 holes)
A7: SUMMARY | F7: SUMMARY | K7: SUMMARY
B9: GOLF CONSTRUCTION ITEMS | D9: Total(s) | G9: GOLF CONSTRUCTION ITEMS | I9: Total(s) | L9: GOLF CONSTRUCTION ITEMS | N9: Total(s)
A11: 1 | B11: GENERAL SITE PREPARATION | D11: ='Practice Facilties'!F12 -> 277386.64 | F11: 1 | G11: GENERAL SITE PREPARATION | I11: ='Two PGs'!F11 -> 71610 | K11: 1 | L11: GENERAL SITE PREPARATION | N11: ='Re-Build Bunkers on the 27'!F11 -> 574705.73
A13: 2 | B13: EARTHWORK | D13: ='Practice Facilties'!F18 -> 28260 | F13: 2 | G13: EARTHWORK | I13: ='Two PGs'!F17 -> 9280 | K13: 2 | L13: EARTHWORK | N13: ='Re-Build Bunkers on the 27'!F17 -> 17115
A15: 3 | B15: STORM DRAINAGE AND EROSION CONTROL | D15: ='Practice Facilties'!F26 -> 151417.82 | F15: 3 | G15: STORM DRAINAGE AND EROSION CONTROL | I15: ='Two PGs'!F25 -> 27561.52 | K15: 3 | L15: STORM DRAINAGE AND EROSION CONTROL | N15: ='Re-Build Bunkers on the 27'!F25 -> 93700.35
A17: 4 | B17: SHAPING | D17: ='Practice Facilties'!F32 -> 74800 | F17: 4 | G17: SHAPING | I17: ='Two PGs'!F31 -> 14000 | K17: 4 | L17: SHAPING | N17: ='Re-Build Bunkers on the 27'!F31 -> 45500
A19: 5 | B19: GOLF COURSE DRAINAGE | D19: ='Practice Facilties'!F42 -> 82536.33 | F19: 5 | G19: GOLF COURSE DRAINAGE | I19: ='Two PGs'!F41 -> 37784.1 | K19: 5 | L19: GOLF COURSE DRAINAGE | N19: ='Re-Build Bunkers on the 27'!F41 -> 418656.23
A21: 6 | B21: GREEN CONSTRUCTION | D21: ='Practice Facilties'!F50 -> 173286 | F21: 6 | G21: GREEN CONSTRUCTION | I21: ='Two PGs'!F49 -> 349288 | K21: 6 | L21: GREEN CONSTRUCTION | N21: ='Re-Build Bunkers on the 27'!F49 -> 0
A23: 7 | B23: TEE CONSTRUCTION | D23: ='Practice Facilties'!F57 -> 330425 | F23: 7 | G23: EVENT LAWN | I23: ='Two PGs'!F56 -> 35878 | K23: 7 | L23: TEE CONSTRUCTION | N23: ='Re-Build Bunkers on the 27'!F56 -> 0
A25: 8 | B25: BUNKER CONSTRUCTION | D25: ='Practice Facilties'!F65 -> 33987.36 | F25: 8 | G25: BUNKER CONSTRUCTION | I25: ='Two PGs'!F64 -> 0 | K25: 8 | L25: BUNKER CONSTRUCTION | N25: ='Re-Build Bunkers on the 27'!F64 -> 1793810
A27: 9 | B27: CONCRETE CART PATH AND CART PARKING | D27: ='Practice Facilties'!F72 -> 169303.34 | F27: 9 | G27: CONCRETE CART PATH AND CART PARKING | I27: ='Two PGs'!F71 -> 17578.92 | K27: 9 | L27: CONCRETE CART PATH AND CART PARKING | N27: ='Re-Build Bunkers on the 27'!F71 -> 0
A29: 10 | B29: FINISH GRADING | D29: ='Practice Facilties'!F77 -> 55000 | F29: 10 | G29: FINISH GRADING | I29: ='Two PGs'!F76 -> 17000 | K29: 10 | L29: FINISH GRADING | N29: ='Re-Build Bunkers on the 27'!F76 -> 63750
A31: 11 | B31: GRASSING | D31: ='Practice Facilties'!F91 -> 282809.12 | F31: 11 | G31: GRASSING | I31: ='Two PGs'!F89 -> 65934.2 | K31: 11 | L31: GRASSING | N31: ='Re-Build Bunkers on the 27'!F89 -> 308312
A33: 12 | B33: IRRIGATION "ALLOWANCE" | D33: 275000 | F33: 12 | G33: IRRIGATION "ALLOWANCE" | I33: 75000 | K33: 12 | L33: IRRIGATION "ALLOWANCE" | N33: 75000
A35: 13 | B35: TREE WORK "ALLOWANCE" | C35: by owner | F35: 13 | G35: TREE WORK "ALLOWANCE" by owner | K35: 13 | L35: TREE WORK "ALLOWANCE" by owner
C37: Total | D37: =SUM(D11:D35) -> 1934211.6 | H37: Total | I37: =SUM(I11:I35) -> 720914.74 | M37: Total | N37: =SUM(N11:N35) -> 3390549.3
M41: Total of Three Projects | N41: =SUM(D37+I37+N37) -> 6045675.7
M43: Contingency @ 10% | N43: =SUM(N41*0.1) -> 604567.57
M45: Total with Contingency | N45: =SUM(N41+N43) -> 6650243.2

Sheet Practice Facilties
A1: Practice Facilities (Practice Range and Short Game Area)
A3: SECTION | B3: DESCRIPTION | C3: UNIT | D3: ESTIMATED QUANTITIES | E3: UNIT PRICE | F3: SUBTOTAL
A4: 1 | B4: GENERAL SITE PREPARATION
A5: 1.1 | B5: Mobilization, Supervision, General Conditions, As-Builts, and Housing | C5: LS | D5: 1 | E5: 145000 | F5: 145000
A6: 1.2 | B6: Roto - tilling of All Areas to be Regrassed; Owner to Spray Out all Areas to be Re-grassed. After Spraying but Prior to Work Commencing; An Aggressive Tilling Procedure Must Completed by Bomag Wherever Possible to Completely Destroy all Plant Material and Leave a Dirt Condition. Where Bomag is not Feasible, Utilize Typical Roto-till Equipment. | C6: AC | D6: 11 | E6: 1909.24 | F6: =D6*E6 -> 21001.64
A7: 1.3 | B7: Demo of Existing Greens to be Replaced - Old Greensmix to be Harvested, Stockpiled, and Spread for New Target Greens; Gravel, and Other Debris Disposed of in Bury Pits; Old Pipe to be Disposed of In Dumpsters | C7: SF | D7: 5000 | E7: 0.71 | F7: =D7*E7 -> 3550
A8: 1.4 | B8: Demo of Existing Bunkers to be Replaced - Old Bunker Sand to be Harvested and Stockpiled and Spread for New Green Surrounds and Fairway area in Body of Range; Gravel, Liner, and Other Debris Disposed of in Bury Pits; Old Pipe to be Disposed of In Dumpsters | C8: SF | D8: 8500 | E8: 1.99 | F8: =D8*E8 -> 16915
A9: 1.5 | B9: Demo of Existing CONCRETE Cart Paths (Assume 4" of Concrete x 8' Width on All Paths) and Haul to Bury Pits throughout the Site, Assume at least 3 Smaller Bury Pits can be Utilized throughout the Property | C9: SF | D9: 12000 | E9: 0.6 | F9: =D9*E9 -> 7200
A10: 1.6 | B10: Demo of Existing Practice Tee(s) to be Replaced - Old Sand to be Harvested (assume 9 inches can be harvested) and Stockpiled and Spread for new Practice Tees; Gravel, Liner, and Other Debris Disposed of in Bury Pits; Old Pipe to be Disposed of In Dumpsters | C10: SF | D10: 50000 | E10: 1.54 | F10: =D10*E10 -> 77000
A11: 1.7 | B11: Silt Fence to Protect Golf Features During Construction and Grow In | C11: LF | D11: 1000 | E11: 6.72 | F11: =D11*E11 -> 6720
E12: SUBTOTAL 1 | F12: =SUM(F5:F11) -> 277386.64
A14: SECTION | B14: DESCRIPTION | C14: UNIT | D14: ESTIMATED QUANTITIES | E14: UNIT PRICE | F14: SUBTOTAL
A15: 2 | B15: EARTHWORK
A16: 2.1 | B16: Cuts and Fills - Enhancements to the Golf Course That Require Moving Dirt Throughout the Golf Course by Utilizing On Road Trucking. Includes the Expansion of Other Various Lakes; Include All Necessary Measure for De-watering as Needed. Owner will Assist in Dewatering where applicable. | C16: CY | D16: 3000 | E16: 6.73 | F16: =D16*E16 -> 20190
A17: 2.2 | B17: Architectural Cuts and Fills - Enhancements to the Golf Course That Require Moving Dirt Throughout the Golf Course - Assume Small Off Road Equipment for Hauling | C17: CY | D17: 1500 | E17: 5.38 | F17: =D17*E17 -> 8070
E18: SUBTOTAL 2 | F18: =SUM(F16:F17) -> 28260
A20: SECTION | B20: DESCRIPTION | C20: UNIT | D20: ESTIMATED QUANTITIES | E20: UNIT PRICE | F20: SUBTOTAL
A21: 3 | B21: STORM DRAINAGE AND EROSION CONTROL (Construction Documents and Quantities Provided by Project Engineer)
A22: 3.1 | B22: Erosion Control Measures Silt Fence - ALLOWANCE | C22: LF | D22: 5000 | E22: 6.72 | F22: =D22*E22 -> 33600
A23: 3.2 | B23: 12" Solid Drainage Pipe and Associated Structures - ALLOWANCE | C23: LF | D23: 1000 | E23: 36.83 | F23: =D23*E23 -> 36830
A24: 3.3 | B24: 8" Solid Drainage Pipe and Associated Structures - ALLOWANCE | C24: LF | D24: 1500 | E24: 26.62 | F24: =D24*E24 -> 39930
A25: 3.4 | B25: Demo Existing Storm Pipe and Dispose of Materials in Dumpsters at Golf Maintenance | C25: AL | D25: 1 | E25: 41057.82 | F25: =D25*E25 -> 41057.82
E26: SUBTOTAL 3 | F26: =SUM(F22:F25) -> 151417.82
A28: SECTION | B28: DESCRIPTION | C28: UNIT | D28: ESTIMATED QUANTITIES | E28: UNIT PRICE | F28: SUBTOTAL
A29: 4 | B29: SHAPING
B30: Shaping - Includes ALL disturbed areas generally described as Green Complexes, new Bunkers, re-shaping of Tees, Cart Paths and Cart Parking
A31: 4.1 | B31: Completely Shape All Disturbed Areas within Golf Course Envelope Including, but Not Limited to: Tees, Greens, Bunkers, Fairways, Roughs, Out of Play Areas, and Cart Paths/Maintenance Trail. | C31: AC | D31: =D6 -> 11 | E31: 6800 | F31: =D31*E31 -> 74800
E32: SUBTOTAL 4 | F32: =SUM(F31:F31) -> 74800
A34: SECTION | B34: DESCRIPTION | C34: UNIT | D34: ESTIMATED QUANTITIES | E34: UNIT PRICE | F34: SUBTOTAL
A35: 5 | B35: GOLF COURSE DRAINAGE
B36: Large (> 8") Pipe Storm Drainage System Will be Designed by Engineer. Golf Course Drainage Refers to All Pipes Necessary to Drain Small Golf Course Depressions in Fairways, Roughs, Out of Play Areas and Other Miscellaneous Drainage that Ties Into Storm Drainage System.
A37: 5.1 | B37: 4" HDPE Solid Pipe, w/Wire - ALLOWANCE | C37: LF | D37: 1500 | E37: 14.43 | F37: =D37*E37 -> 21645
A38: 5.2 | B38: 6" HDPE Solid Pipe, w/Wire - ALLOWANCE | C38: LF | D38: 750 | E38: 18.97 | F38: =D38*E38 -> 14227.5
A39: 5.3 | B39: Swale Drainage - 4” ADS N-12 (or approved equal) Slotted Drain Pipe, Stone Trench, and Wire. Trench Dimensions to be 1’ Wide by 2’ Deep. To be Installed Around Greens and Other High Traffic Areas. - ALLOWANCE | C39: LF | D39: 1500 | E39: 22.12 | F39: =D39*E39 -> 33180
A40: 5.4 | B40: Basins in Turf - 12" Cast Iron Grate with Perforated Riser Surrounded by Gravel and Sand. See Perforated Riser Drain Basin Detail for More Information. - ALLOWANCE | C40: EA | D40: 15 | E40: 560.49 | F40: =D40*E40 -> 8407.35
A41: 5.5 | B41: Basins in Turf - 18" Cast Iron Grate with Perforated Riser Surrounded by Gravel and Sand. See Perforated Riser Drain Basin Detail for More Information. - ALLOWANCE | C41: EA | D41: 6 | E41: 846.08 | F41: =D41*E41 -> 5076.48
E42: SUBTOTAL 5 | F42: =SUM(F37:F41) -> 82536.33
A44: 6 | B44: GREEN CONSTRUCTION (U.S.G.A.) - Two Short Game Area Greens at +/- 5,000 s.f. each and Re-build Player Putting Green at +/- 3,000 s.f.
A45: 6.1 | B45: 4" HDPE Perforated Pipe w/Stone, w/Wire - Sub-grade Drainage | C45: LF | D45: =SUM(D47*0.15) -> 1950 | E45: 18 | F45: =D45*E45 -> 35100
A46: 6.2 | B46: 4" HDPE Solid Pipe w/Wire - Exit Drains from Green Sub-grade | C46: LF | D46: =SUM(D47*0.12) -> 1560 | E46: 13.35 | F46: =D46*E46 -> 20826
...

Sheet Two PGs
A1: Two Large Putting Greens
A3: SECTION | B3: DESCRIPTION | C3: UNIT | D3: ESTIMATED QUANTITIES | E3: UNIT PRICE | F3: SUBTOTAL
A4: 1 | B4: GENERAL SITE PREPARATION
A5: 1.1 | B5: Mobilization, Supervision, General Conditions, As-Builts, and Housing | C5: LS | D5: 1 | E5: 50000 | F5: =D5*E5 -> 50000
A6: 1.2 | B6: Roto - tilling of All Areas to be Regrassed; Owner to Spray Out all Areas to be Re-grassed. After Spraying but Prior to Work Commencing; An Aggressive Tilling Procedure Must Completed by Bomag Wherever Possible to Completely Destroy all Plant Material and Leave a Dirt Condition. Where Bomag is not Feasible, Utilize Typical Roto-till Equipment. | C6: AC | D6: 2 | E6: 2150 | F6: =D6*E6 -> 4300
A7: 1.3 | B7: Demo of Existing Greens to be Replaced - Old Greensmix to be Harvested, Stockpiled, and Spread for New Target Greens; Gravel, and Other Debris Disposed of in Bury Pits; Old Pipe to be Disposed of In Dumpsters | C7: SF | D7: 20000 | E7: 0.7 | F7: =D7*E7 -> 14000
A8: 1.4 | B8: Demo of Existing Bunkers to be Replaced - Old Bunker Sand to be Harvested and Stockpiled with Greensmix and Spread for New Tees; Gravel, Liner, and Other Debris Disposed of in Bury Pits; Old Pipe to be Disposed of In Dumpsters | C8: SF | D8: 0 | F8: =D8*E8 -> 0
A9: 1.5 | B9: Demo of Existing CONCRETE Cart Paths (Assume 4" of Concrete x 8' Width on All Paths) and Haul to Bury Pits throughout the Site, Assume at least 3 Smaller Bury Pits can be Utilized throughout the Property | C9: SF | D9: 0 | F9: =D9*E9 -> 0
A10: 1.6 | B10: Silt Fence to Protect Golf Features During Construction and Grow In | C10: LF | D10: 500 | E10: 6.62 | F10: =D10*E10 -> 3310
E11: SUBTOTAL 1 | F11: =SUM(F5:F10) -> 71610
A13: SECTION | B13: DESCRIPTION | C13: UNIT | D13: ESTIMATED QUANTITIES | E13: UNIT PRICE | F13: SUBTOTAL
A14: 2 | B14: EARTHWORK
A15: 2.1 | B15: Cuts and Fills - Enhancements to the Golf Course That Require Moving Dirt Throughout the Golf Course by Utilizing On Road Trucking. Includes the Expansion of Other Various Lakes; Include All Necessary Measure for De-watering as Needed. Owner will Assist in Dewatering where applicable. | C15: CY | D15: 1000 | E15: 6.63 | F15: =D15*E15 -> 6630
A16: 2.2 | B16: Architectural Cuts and Fills - Enhancements to the Golf Course That Require Moving Dirt Throughout the Golf Course - Assume Small Off Road Equipment for Hauling | C16: CY | D16: 500 | E16: 5.3 | F16: =D16*E16 -> 2650
E17: SUBTOTAL 2 | F17: =SUM(F15:F16) -> 9280
A19: SECTION | B19: DESCRIPTION | C19: UNIT | D19: ESTIMATED QUANTITIES | E19: UNIT PRICE | F19: SUBTOTAL
A20: 3 | B20: STORM DRAINAGE AND EROSION CONTROL (Construction Documents and Quantities Provided by Project Engineer)
A21: 3.1 | B21: Erosion Control Measures Silt Fence - ALLOWANCE | C21: LF | D21: 1500 | E21: 6.62 | F21: =D21*E21 -> 9930
A22: 3.2 | B22: 12" Solid Drainage Pipe and Associated Structures - ALLOWANCE | C22: LF | D22: 0 | F22: =D22*E22 -> 0
A23: 3.3 | B23: 8" Solid Drainage Pipe and Associated Structures - ALLOWANCE | C23: LF | D23: 500 | E23: 26.23 | F23: =D23*E23 -> 13115
A24: 3.4 | B24: Demo Existing Storm Pipe and Dispose of Materials in Dumpsters at Golf Maintenance | C24: AL | D24: 1 | E24: 4516.52 | F24: =D24*E24 -> 4516.52
E25: SUBTOTAL 3 | F25: =SUM(F21:F24) -> 27561.52
A27: SECTION | B27: DESCRIPTION | C27: UNIT | D27: ESTIMATED QUANTITIES | E27: UNIT PRICE | F27: SUBTOTAL
A28: 4 | B28: SHAPING
B29: Shaping - Includes ALL disturbed areas generally described as Green Complexes and surrounding turf areas, Cart Paths and Cart Parking
A30: 4.1 | B30: Completely Shape All Disturbed Areas within Golf Course Envelope Including, but Not Limited to: Tees, Greens, Bunkers, Fairways, Roughs, Out of Play Areas, and Cart Paths/Maintenance Trail. | C30: AC | D30: =D6 -> 2 | E30: 7000 | F30: =D30*E30 -> 14000
E31: SUBTOTAL 4 | F31: =SUM(F30:F30) -> 14000
A33: SECTION | B33: DESCRIPTION | C33: UNIT | D33: ESTIMATED QUANTITIES | E33: UNIT PRICE | F33: SUBTOTAL
A34: 5 | B34: GOLF COURSE DRAINAGE
B35: Large (> 8") Pipe Storm Drainage System Will be Designed by Engineer. Golf Course Drainage Refers to All Pipes Necessary to Drain Small Golf Course Depressions in Fairways, Roughs, Out of Play Areas and Other Miscellaneous Drainage that Ties Into Storm Drainage System.
A36: 5.1 | B36: 4" HDPE Solid Pipe, w/Wire - ALLOWANCE | C36: LF | D36: 1000 | E36: 14.22 | F36: =D36*E36 -> 14220
A37: 5.2 | B37: 6" HDPE Solid Pipe, w/Wire - ALLOWANCE | C37: LF | D37: 500 | E37: 18.7 | F37: =D37*E37 -> 9350
A38: 5.3 | B38: Swale Drainage - 4” ADS N-12 (or approved equal) Slotted Drain Pipe, Stone Trench, and Wire. Trench Dimensions to be 1’ Wide by 2’ Deep. To be Installed Around Greens and Other High Traffic Areas. - ALLOWANCE | C38: LF | D38: 500 | E38: 21.8 | F38: =D38*E38 -> 10900
A39: 5.4 | B39: Basins in Turf - 12" Cast Iron Grate with Perforated Riser Surrounded by Gravel and Sand. See Perforated Riser Drain Basin Detail for More Information. - ALLOWANCE | C39: EA | D39: 6 | E39: 552.35 | F39: =D39*E39 -> 3314.1
A40: 5.5 | B40: Basins in Turf - 18" Cast Iron Grate with Perforated Riser Surrounded by Gravel and Sand. See Perforated Riser Drain Basin Detail for More Information. - ALLOWANCE | C40: EA | D40: 0 | F40: =D40*E40 -> 0
E41: SUBTOTAL 5 | F41: =SUM(F36:F40) -> 37784.1
A43: 6 | B43: GREEN CONSTRUCTION (U.S.G.A.) - Two Putting Greens at +/- 15,000 s.f. each
A44: 6.1 | B44: 4" HDPE Perforated Pipe w/Stone, w/Wire - Sub-grade Drainage | C44: LF | D44: =SUM(D46*0.15) -> 4500 | E44: 18 | F44: =D44*E44 -> 81000
A45: 6.2 | B45: 4" HDPE Solid Pipe w/Wire - Exit Drains from Green Sub-grade | C45: LF | D45: 500 | E45: 13.16 | F45: =D45*E45 -> 6580
A46: 6.3 | B46: 4" Gravel Layer - Granite Gravel to Meet USGA Specifications | C46: SF | D46: =SUM(20000+10000) -> 30000 | E46: 1.81 | F46: =D46*E46 -> 54300
...

Sheet Re-Build Bunkers on the 27
A1: Re-Build all Bunkers on the 27 Holes
A3: SECTION | B3: DESCRIPTION | C3: UNIT | D3: ESTIMATED QUANTITIES | E3: UNIT PRICE | F3: SUBTOTAL
A4: 1 | B4: GENERAL SITE PREPARATION
A5: 1.1 | B5: Mobilization, Supervision, General Conditions, As-Builts, and Housing | C5: LS | D5: 1 | E5: 225000 | F5: 225000
A6: 1.2 | B6: Roto - tilling of All Areas to be Regrassed; Owner to Spray Out all Areas to be Re-grassed. After Spraying but Prior to Work Commencing; An Aggressive Tilling Procedure Must Completed by Bomag Wherever Possible to Completely Destroy all Plant Material and Leave a Dirt Condition. Where Bomag is not Feasible, Utilize Typical Roto-till Equipment. | C6: AC | D6: 7 | E6: 1733.39 | F6: =D6*E6 -> 12133.73
A7: 1.3 | B7: Demo of Existing Greens to be Replaced - Old Greensmix to be Harvested, Stockpiled, and Spread for New Tees; Gravel, and Other Debris Disposed of in Bury Pits; Old Pipe to be Disposed of In Dumpsters | C7: SF | D7: 0 | F7: =D7*E7 -> 0
A8: 1.4 | B8: Demo of Existing Bunkers to be Replaced - Old Bunker Sand to be Harvested and Stockpiled at Golf Maintenance (for screening by Owners); Gravel, Liner, and Other Debris Disposed of in Bury Pits; Old Pipe to be Disposed of In Dumpsters | C8: SF | D8: =SUM(5*43560)-8500 -> 209300 | E8: 1.54 | F8: =D8*E8 -> 322322
A9: 1.5 | B9: Demo of Existing CONCRETE Cart Paths (Assume 4" of Concrete x 8' Width on All Paths) and Haul to Bury Pits throughout the Site, Assume at least 3 Smaller Bury Pits can be Utilized throughout the Property | C9: SF | D9: 0 | F9: =D9*E9 -> 0
A10: 1.6 | B10: Silt Fence to Protect Golf Features During Construction and Grow In | C10: LF | D10: 2500 | E10: 6.1 | F10: =D10*E10 -> 15250
E11: SUBTOTAL 1 | F11: =SUM(F5:F10) -> 574705.73
A13: SECTION | B13: DESCRIPTION | C13: UNIT | D13: ESTIMATED QUANTITIES | E13: UNIT PRICE | F13: SUBTOTAL
A14: 2 | B14: EARTHWORK
A15: 2.1 | B15: Cuts and Fills - Enhancements to the Golf Course That Require Moving Dirt Throughout the Golf Course by Utilizing On Road Trucking. Includes the Expansion of Other Various Lakes; Include All Necessary Measure for De-watering as Needed. Owner will Assist in Dewatering where applicable. | C15: CY | D15: 2500 | E15: 4.89 | F15: =D15*E15 -> 12225
A16: 2.2 | B16: Architectural Cuts and Fills - Enhancements to the Golf Course That Require Moving Dirt Throughout the Golf Course - Assume Small Off Road Equipment for Hauling | C16: CY | D16: 1000 | E16: 4.89 | F16: =D16*E16 -> 4890
E17: SUBTOTAL 2 | F17: =SUM(F15:F16) -> 17115
A19: SECTION | B19: DESCRIPTION | C19: UNIT | D19: ESTIMATED QUANTITIES | E19: UNIT PRICE | F19: SUBTOTAL
A20: 3 | B20: STORM DRAINAGE AND EROSION CONTROL (Construction Documents and Quantities Provided by Project Engineer)
A21: 3.1 | B21: Erosion Control Measures Silt Fence - ALLOWANCE | C21: LF | D21: 5000 | E21: 6.1 | F21: =D21*E21 -> 30500
A22: 3.2 | B22: 12" Solid Drainage Pipe and Associated Structures - ALLOWANCE | C22: LF | D22: 0 | F22: =D22*E22 -> 0
A23: 3.3 | B23: 8" Solid Drainage Pipe and Associated Structures - ALLOWANCE | C23: LF | D23: 2500 | E23: 24.17 | F23: =D23*E23 -> 60425
A24: 3.4 | B24: Demo Existing Storm Pipe and Dispose of Materials in Dumpsters at Golf Maintenance | C24: AL | D24: 1 | E24: 2775.35 | F24: =D24*E24 -> 2775.35
E25: SUBTOTAL 3 | F25: =SUM(F21:F24) -> 93700.35
A27: SECTION | B27: DESCRIPTION | C27: UNIT | D27: ESTIMATED QUANTITIES | E27: UNIT PRICE | F27: SUBTOTAL
A28: 4 | B28: SHAPING
B29: Shaping - Includes ALL disturbed areas generally described as adjacent Turf Areas to existing bunkers. Goal of shaping these areas is to divert water away from bunkers and into Catch Basins or Forest Areas
A30: 4.1 | B30: Completely Shape All Disturbed Areas within the "limits of disturbance. Bunker Shaping in line item 8.1 | C30: AC | D30: 7 | E30: 6500 | F30: =D30*E30 -> 45500
E31: SUBTOTAL 4 | F31: =SUM(F30:F30) -> 45500
A33: SECTION | B33: DESCRIPTION | C33: UNIT | D33: ESTIMATED QUANTITIES | E33: UNIT PRICE | F33: SUBTOTAL
A34: 5 | B34: GOLF COURSE DRAINAGE
B35: Large (> 8") Pipe Storm Drainage System Will be Designed by Engineer. Golf Course Drainage Refers to All Pipes Necessary to Drain Small Golf Course Depressions in Fairways, Roughs, Out of Play Areas and Other Miscellaneous Drainage that Ties Into Storm Drainage System.
A36: 5.1 | B36: 4" HDPE Solid Pipe, w/Wire - ALLOWANCE | C36: LF | D36: 5000 | E36: 13.1 | F36: =D36*E36 -> 65500
A37: 5.2 | B37: 6" HDPE Solid Pipe, w/Wire - ALLOWANCE | C37: LF | D37: 2500 | E37: 17.23 | F37: =D37*E37 -> 43075
A38: 5.3 | B38: Swale Drainage - 4” ADS N-12 (or approved equal) Slotted Drain Pipe, Stone Trench, and Wire. Trench Dimensions to be 1’ Wide by 2’ Deep. To be Installed Around Greens and Other High Traffic Areas. - ALLOWANCE | C38: LF | D38: =SUM(27*500) -> 13500 | E38: 20.08 | F38: =D38*E38 -> 271080
A39: 5.4 | B39: Basins in Turf - 12" Cast Iron Grate with Perforated Riser Surrounded by Gravel and Sand. See Perforated Riser Drain Basin Detail for More Information. - ALLOWANCE | C39: EA | D39: =SUM(27*2) -> 54 | E39: 508.87 | F39: =D39*E39 -> 27478.98
A40: 5.5 | B40: Basins in Turf - 18" Cast Iron Grate with Perforated Riser Surrounded by Gravel and Sand. See Perforated Riser Drain Basin Detail for More Information. - ALLOWANCE | C40: EA | D40: 15 | E40: 768.15 | F40: =D40*E40 -> 11522.25
E41: SUBTOTAL 5 | F41: =SUM(F36:F40) -> 418656.23
A43: 6 | B43: GREEN CONSTRUCTION (U.S.G.A.)
A44: 6.1 | B44: 4" HDPE Perforated Pipe w/Stone, w/Wire - Sub-grade Drainage | C44: LF | D44: =SUM(D46*0.15) -> 0 | F44: =D44*E44 -> 0
A45: 6.2 | B45: 4" HDPE Solid Pipe w/Wire - Exit Drains from Green Sub-grade | C45: LF | D45: =SUM(D46*0.12) -> 0 | F45: =D45*E45 -> 0
A46: 6.3 | B46: 4" Gravel Layer - Granite Gravel to Meet USGA Specifications | C46: SF | D46: 0 | F46: =D46*E46 -> 0
...
